[2023-05-18T13:29:44.463+0000] {taskinstance.py:1083} INFO - Dependencies all met for <TaskInstance: my_third_dagV5.fo manual__2023-05-18T13:14:20.033279+00:00 [queued]>
[2023-05-18T13:29:44.474+0000] {taskinstance.py:1083} INFO - Dependencies all met for <TaskInstance: my_third_dagV5.fo manual__2023-05-18T13:14:20.033279+00:00 [queued]>
[2023-05-18T13:29:44.474+0000] {taskinstance.py:1279} INFO - 
--------------------------------------------------------------------------------
[2023-05-18T13:29:44.474+0000] {taskinstance.py:1280} INFO - Starting attempt 4 of 4
[2023-05-18T13:29:44.474+0000] {taskinstance.py:1281} INFO - 
--------------------------------------------------------------------------------
[2023-05-18T13:29:44.492+0000] {taskinstance.py:1300} INFO - Executing <Task(PythonOperator): fo> on 2023-05-18 13:14:20.033279+00:00
[2023-05-18T13:29:44.497+0000] {standard_task_runner.py:55} INFO - Started process 30280 to run task
[2023-05-18T13:29:44.500+0000] {standard_task_runner.py:82} INFO - Running: ['***', 'tasks', 'run', 'my_third_dagV5', 'fo', 'manual__2023-05-18T13:14:20.033279+00:00', '--job-id', '183', '--raw', '--subdir', 'DAGS_FOLDER/dag3.py', '--cfg-path', '/tmp/tmpptp4g4vg']
[2023-05-18T13:29:44.500+0000] {standard_task_runner.py:83} INFO - Job 183: Subtask fo
[2023-05-18T13:29:44.594+0000] {task_command.py:388} INFO - Running <TaskInstance: my_third_dagV5.fo manual__2023-05-18T13:14:20.033279+00:00 [running]> on host 031cfb56e8fb
[2023-05-18T13:29:44.683+0000] {taskinstance.py:1509} INFO - Exporting the following env vars:
AIRFLOW_CTX_DAG_OWNER=***
AIRFLOW_CTX_DAG_ID=my_third_dagV5
AIRFLOW_CTX_TASK_ID=fo
AIRFLOW_CTX_EXECUTION_DATE=2023-05-18T13:14:20.033279+00:00
AIRFLOW_CTX_TRY_NUMBER=4
AIRFLOW_CTX_DAG_RUN_ID=manual__2023-05-18T13:14:20.033279+00:00
[2023-05-18T13:29:46.136+0000] {taskinstance.py:1768} ERROR - Task failed with exception
Traceback (most recent call last):
  File "/home/airflow/.local/lib/python3.7/site-packages/airflow/operators/python.py", line 175, in execute
    return_value = self.execute_callable()
  File "/home/airflow/.local/lib/python3.7/site-packages/airflow/operators/python.py", line 192, in execute_callable
    return self.python_callable(*self.op_args, **self.op_kwargs)
  File "/opt/airflow/dags/dag3.py", line 81, in foo1
    .config([("spark.jars", "/java/postgresql-42.6.0.jar"), ('spark.executor.memory', '8g'), ('spark.executor.cores', '4'), ('spark.cores.max', '4'), ('spark.driver.memory','8g')]) \
  File "/home/airflow/.local/lib/python3.7/site-packages/pyspark/sql/session.py", line 306, in config
    self._options[cast(str, key)] = value
TypeError: unhashable type: 'list'
[2023-05-18T13:29:46.143+0000] {taskinstance.py:1323} INFO - Marking task as FAILED. dag_id=my_third_dagV5, task_id=fo, execution_date=20230518T131420, start_date=20230518T132944, end_date=20230518T132946
[2023-05-18T13:29:46.174+0000] {standard_task_runner.py:105} ERROR - Failed to execute job 183 for task fo (unhashable type: 'list'; 30280)
[2023-05-18T13:29:46.193+0000] {local_task_job.py:208} INFO - Task exited with return code 1
[2023-05-18T13:29:46.216+0000] {taskinstance.py:2578} INFO - 0 downstream tasks scheduled from follow-on schedule check
