[2023-04-15T21:08:08.578+0000] {taskinstance.py:1083} INFO - Dependencies all met for <TaskInstance: my_third_dagV1.fo manual__2023-04-15T21:08:05.040745+00:00 [queued]>
[2023-04-15T21:08:08.585+0000] {taskinstance.py:1083} INFO - Dependencies all met for <TaskInstance: my_third_dagV1.fo manual__2023-04-15T21:08:05.040745+00:00 [queued]>
[2023-04-15T21:08:08.585+0000] {taskinstance.py:1279} INFO - 
--------------------------------------------------------------------------------
[2023-04-15T21:08:08.585+0000] {taskinstance.py:1280} INFO - Starting attempt 1 of 1
[2023-04-15T21:08:08.585+0000] {taskinstance.py:1281} INFO - 
--------------------------------------------------------------------------------
[2023-04-15T21:08:08.596+0000] {taskinstance.py:1300} INFO - Executing <Task(PythonOperator): fo> on 2023-04-15 21:08:05.040745+00:00
[2023-04-15T21:08:08.601+0000] {standard_task_runner.py:55} INFO - Started process 171 to run task
[2023-04-15T21:08:08.603+0000] {standard_task_runner.py:82} INFO - Running: ['***', 'tasks', 'run', 'my_third_dagV1', 'fo', 'manual__2023-04-15T21:08:05.040745+00:00', '--job-id', '102', '--raw', '--subdir', 'DAGS_FOLDER/dag3.py', '--cfg-path', '/tmp/tmpxu_yxo97']
[2023-04-15T21:08:08.604+0000] {standard_task_runner.py:83} INFO - Job 102: Subtask fo
[2023-04-15T21:08:08.650+0000] {task_command.py:388} INFO - Running <TaskInstance: my_third_dagV1.fo manual__2023-04-15T21:08:05.040745+00:00 [running]> on host 91c57aa8ef24
[2023-04-15T21:08:08.808+0000] {taskinstance.py:1509} INFO - Exporting the following env vars:
AIRFLOW_CTX_DAG_OWNER=***
AIRFLOW_CTX_DAG_ID=my_third_dagV1
AIRFLOW_CTX_TASK_ID=fo
AIRFLOW_CTX_EXECUTION_DATE=2023-04-15T21:08:05.040745+00:00
AIRFLOW_CTX_TRY_NUMBER=1
AIRFLOW_CTX_DAG_RUN_ID=manual__2023-04-15T21:08:05.040745+00:00
[2023-04-15T21:08:23.388+0000] {taskinstance.py:1768} ERROR - Task failed with exception
Traceback (most recent call last):
  File "/home/airflow/.local/lib/python3.7/site-packages/airflow/operators/python.py", line 175, in execute
    return_value = self.execute_callable()
  File "/home/airflow/.local/lib/python3.7/site-packages/airflow/operators/python.py", line 192, in execute_callable
    return self.python_callable(*self.op_args, **self.op_kwargs)
  File "/opt/airflow/dags/dag3.py", line 63, in foo1
    spark=SparkSession.builder.appName('Sparkv1').getOrCreate()
  File "/home/airflow/.local/lib/python3.7/site-packages/pyspark/sql/session.py", line 269, in getOrCreate
    sc = SparkContext.getOrCreate(sparkConf)
  File "/home/airflow/.local/lib/python3.7/site-packages/pyspark/context.py", line 483, in getOrCreate
    SparkContext(conf=conf or SparkConf())
  File "/home/airflow/.local/lib/python3.7/site-packages/pyspark/context.py", line 195, in __init__
    SparkContext._ensure_initialized(self, gateway=gateway, conf=conf)
  File "/home/airflow/.local/lib/python3.7/site-packages/pyspark/context.py", line 417, in _ensure_initialized
    SparkContext._gateway = gateway or launch_gateway(conf)
  File "/home/airflow/.local/lib/python3.7/site-packages/pyspark/java_gateway.py", line 106, in launch_gateway
    raise RuntimeError("Java gateway process exited before sending its port number")
RuntimeError: Java gateway process exited before sending its port number
[2023-04-15T21:08:23.432+0000] {taskinstance.py:1323} INFO - Marking task as FAILED. dag_id=my_third_dagV1, task_id=fo, execution_date=20230415T210805, start_date=20230415T210808, end_date=20230415T210823
[2023-04-15T21:08:23.540+0000] {standard_task_runner.py:105} ERROR - Failed to execute job 102 for task fo (Java gateway process exited before sending its port number; 171)
[2023-04-15T21:08:23.576+0000] {local_task_job.py:208} INFO - Task exited with return code 1
[2023-04-15T21:08:23.587+0000] {taskinstance.py:2578} INFO - 0 downstream tasks scheduled from follow-on schedule check
