[2023-02-10T09:25:22.598+0000] {taskinstance.py:1083} INFO - Dependencies all met for <TaskInstance: my_first_dag.calculate_optimal_prices manual__2023-02-10T09:15:01.954841+00:00 [queued]>
[2023-02-10T09:25:22.610+0000] {taskinstance.py:1083} INFO - Dependencies all met for <TaskInstance: my_first_dag.calculate_optimal_prices manual__2023-02-10T09:15:01.954841+00:00 [queued]>
[2023-02-10T09:25:22.611+0000] {taskinstance.py:1279} INFO - 
--------------------------------------------------------------------------------
[2023-02-10T09:25:22.611+0000] {taskinstance.py:1280} INFO - Starting attempt 4 of 4
[2023-02-10T09:25:22.611+0000] {taskinstance.py:1281} INFO - 
--------------------------------------------------------------------------------
[2023-02-10T09:25:22.628+0000] {taskinstance.py:1300} INFO - Executing <Task(PythonOperator): calculate_optimal_prices> on 2023-02-10 09:15:01.954841+00:00
[2023-02-10T09:25:22.635+0000] {standard_task_runner.py:55} INFO - Started process 28821 to run task
[2023-02-10T09:25:22.638+0000] {standard_task_runner.py:82} INFO - Running: ['***', 'tasks', 'run', 'my_first_dag', 'calculate_optimal_prices', 'manual__2023-02-10T09:15:01.954841+00:00', '--job-id', '58', '--raw', '--subdir', 'DAGS_FOLDER/dag1.py', '--cfg-path', '/tmp/tmp5lppk04o']
[2023-02-10T09:25:22.638+0000] {standard_task_runner.py:83} INFO - Job 58: Subtask calculate_optimal_prices
[2023-02-10T09:25:22.755+0000] {task_command.py:388} INFO - Running <TaskInstance: my_first_dag.calculate_optimal_prices manual__2023-02-10T09:15:01.954841+00:00 [running]> on host 47e55e08a495
[2023-02-10T09:25:22.845+0000] {taskinstance.py:1509} INFO - Exporting the following env vars:
AIRFLOW_CTX_DAG_OWNER=***
AIRFLOW_CTX_DAG_ID=my_first_dag
AIRFLOW_CTX_TASK_ID=calculate_optimal_prices
AIRFLOW_CTX_EXECUTION_DATE=2023-02-10T09:15:01.954841+00:00
AIRFLOW_CTX_TRY_NUMBER=4
AIRFLOW_CTX_DAG_RUN_ID=manual__2023-02-10T09:15:01.954841+00:00
[2023-02-10T09:25:29.519+0000] {logging_mixin.py:137} INFO - a = 104126.5008 ± 53599.6971, доверительный интервал α=5% [-5052.5094 ; 213305.5111]
[2023-02-10T09:25:29.531+0000] {logging_mixin.py:137} INFO - b = -1986910.3008 ± 1130139.7939, доверительный интервал α=5% [-4288929.7297 ; 315109.1282]
[2023-02-10T09:25:29.612+0000] {logging_mixin.py:137} INFO - a = 163.5409 ± 110.9425, доверительный интервал α=5% [-62.4415 ; 389.5234]
[2023-02-10T09:25:29.612+0000] {logging_mixin.py:137} INFO - b = -2500.6969 ± 2254.2024, доверительный интервал α=5% [-7092.3568 ; 2090.9631]
[2023-02-10T09:25:29.747+0000] {logging_mixin.py:137} INFO - a = 12586.4627 ± 6325.4469, доверительный интервал α=5% [-298.0509 ; 25470.9763]
[2023-02-10T09:25:29.774+0000] {logging_mixin.py:137} INFO - b = -362717.2361 ± 202708.0127, доверительный интервал α=5% [-775619.9461 ; 50185.4740]
[2023-02-10T09:25:30.492+0000] {taskinstance.py:1768} ERROR - Task failed with exception
Traceback (most recent call last):
  File "/home/airflow/.local/lib/python3.7/site-packages/sqlalchemy/engine/base.py", line 1881, in _execute_context
    cursor, statement, parameters, context
  File "/home/airflow/.local/lib/python3.7/site-packages/sqlalchemy/dialects/postgresql/psycopg2.py", line 988, in do_executemany
    **kwargs
  File "/home/airflow/.local/lib/python3.7/site-packages/psycopg2/extras.py", line 1299, in execute_values
    cur.execute(b''.join(parts))
psycopg2.errors.UndefinedColumn: column "pph_id" of relation "price_history" does not exist
LINE 1: INSERT INTO price_history (pph_id, date, price, product_id) ...
                                   ^


The above exception was the direct cause of the following exception:

Traceback (most recent call last):
  File "/home/airflow/.local/lib/python3.7/site-packages/airflow/operators/python.py", line 175, in execute
    return_value = self.execute_callable()
  File "/home/airflow/.local/lib/python3.7/site-packages/airflow/operators/python.py", line 192, in execute_callable
    return self.python_callable(*self.op_args, **self.op_kwargs)
  File "/opt/airflow/dags/dag1.py", line 187, in _calculate_optimal_prices
    df_pph.to_sql('price_history', dbConnection, if_exists='append', index=False)
  File "/home/airflow/.local/lib/python3.7/site-packages/pandas/core/generic.py", line 2882, in to_sql
    method=method,
  File "/home/airflow/.local/lib/python3.7/site-packages/pandas/io/sql.py", line 728, in to_sql
    **engine_kwargs,
  File "/home/airflow/.local/lib/python3.7/site-packages/pandas/io/sql.py", line 1770, in to_sql
    **engine_kwargs,
  File "/home/airflow/.local/lib/python3.7/site-packages/pandas/io/sql.py", line 1350, in insert_records
    raise err
  File "/home/airflow/.local/lib/python3.7/site-packages/pandas/io/sql.py", line 1340, in insert_records
    table.insert(chunksize=chunksize, method=method)
  File "/home/airflow/.local/lib/python3.7/site-packages/pandas/io/sql.py", line 967, in insert
    exec_insert(conn, keys, chunk_iter)
  File "/home/airflow/.local/lib/python3.7/site-packages/pandas/io/sql.py", line 882, in _execute_insert
    conn.execute(self.table.insert(), data)
  File "/home/airflow/.local/lib/python3.7/site-packages/sqlalchemy/engine/base.py", line 1380, in execute
    return meth(self, multiparams, params, _EMPTY_EXECUTION_OPTS)
  File "/home/airflow/.local/lib/python3.7/site-packages/sqlalchemy/sql/elements.py", line 335, in _execute_on_connection
    self, multiparams, params, execution_options
  File "/home/airflow/.local/lib/python3.7/site-packages/sqlalchemy/engine/base.py", line 1582, in _execute_clauseelement
    cache_hit=cache_hit,
  File "/home/airflow/.local/lib/python3.7/site-packages/sqlalchemy/engine/base.py", line 1944, in _execute_context
    e, statement, parameters, cursor, context
  File "/home/airflow/.local/lib/python3.7/site-packages/sqlalchemy/engine/base.py", line 2125, in _handle_dbapi_exception
    sqlalchemy_exception, with_traceback=exc_info[2], from_=e
  File "/home/airflow/.local/lib/python3.7/site-packages/sqlalchemy/util/compat.py", line 211, in raise_
    raise exception
  File "/home/airflow/.local/lib/python3.7/site-packages/sqlalchemy/engine/base.py", line 1881, in _execute_context
    cursor, statement, parameters, context
  File "/home/airflow/.local/lib/python3.7/site-packages/sqlalchemy/dialects/postgresql/psycopg2.py", line 988, in do_executemany
    **kwargs
  File "/home/airflow/.local/lib/python3.7/site-packages/psycopg2/extras.py", line 1299, in execute_values
    cur.execute(b''.join(parts))
sqlalchemy.exc.ProgrammingError: (psycopg2.errors.UndefinedColumn) column "pph_id" of relation "price_history" does not exist
LINE 1: INSERT INTO price_history (pph_id, date, price, product_id) ...
                                   ^

[SQL: INSERT INTO price_history (pph_id, date, price, product_id) VALUES (%(pph_id)s, %(date)s, %(price)s, %(product_id)s)]
[parameters: ({'pph_id': 'default', 'date': datetime.datetime(2023, 2, 10, 9, 25, 29, 533625), 'price': 2.716005704706478, 'product_id': '248562'}, {'pph_id': 'default', 'date': datetime.datetime(2023, 2, 10, 9, 25, 29, 636214), 'price': 0.44901528613759234, 'product_id': '136348'}, {'pph_id': 'default', 'date': datetime.datetime(2023, 2, 10, 9, 25, 29, 777873), 'price': 4.230382524046564, 'product_id': '47346'})]
(Background on this error at: https://sqlalche.me/e/14/f405)
[2023-02-10T09:25:30.503+0000] {taskinstance.py:1323} INFO - Marking task as FAILED. dag_id=my_first_dag, task_id=calculate_optimal_prices, execution_date=20230210T091501, start_date=20230210T092522, end_date=20230210T092530
[2023-02-10T09:25:30.640+0000] {standard_task_runner.py:105} ERROR - Failed to execute job 58 for task calculate_optimal_prices ((psycopg2.errors.UndefinedColumn) column "pph_id" of relation "price_history" does not exist
LINE 1: INSERT INTO price_history (pph_id, date, price, product_id) ...
                                   ^

[SQL: INSERT INTO price_history (pph_id, date, price, product_id) VALUES (%(pph_id)s, %(date)s, %(price)s, %(product_id)s)]
[parameters: ({'pph_id': 'default', 'date': datetime.datetime(2023, 2, 10, 9, 25, 29, 533625), 'price': 2.716005704706478, 'product_id': '248562'}, {'pph_id': 'default', 'date': datetime.datetime(2023, 2, 10, 9, 25, 29, 636214), 'price': 0.44901528613759234, 'product_id': '136348'}, {'pph_id': 'default', 'date': datetime.datetime(2023, 2, 10, 9, 25, 29, 777873), 'price': 4.230382524046564, 'product_id': '47346'})]
(Background on this error at: https://sqlalche.me/e/14/f405); 28821)
[2023-02-10T09:25:30.671+0000] {local_task_job.py:208} INFO - Task exited with return code 1
[2023-02-10T09:25:30.703+0000] {taskinstance.py:2578} INFO - 0 downstream tasks scheduled from follow-on schedule check
