[2023-02-09T15:20:36.655+0000] {taskinstance.py:1083} INFO - Dependencies all met for <TaskInstance: my_third_dagV1.fo manual__2023-02-09T15:09:27.365823+00:00 [queued]>
[2023-02-09T15:20:36.663+0000] {taskinstance.py:1083} INFO - Dependencies all met for <TaskInstance: my_third_dagV1.fo manual__2023-02-09T15:09:27.365823+00:00 [queued]>
[2023-02-09T15:20:36.663+0000] {taskinstance.py:1279} INFO - 
--------------------------------------------------------------------------------
[2023-02-09T15:20:36.663+0000] {taskinstance.py:1280} INFO - Starting attempt 5 of 5
[2023-02-09T15:20:36.663+0000] {taskinstance.py:1281} INFO - 
--------------------------------------------------------------------------------
[2023-02-09T15:20:36.684+0000] {taskinstance.py:1300} INFO - Executing <Task(PythonOperator): fo> on 2023-02-09 15:09:27.365823+00:00
[2023-02-09T15:20:36.687+0000] {standard_task_runner.py:55} INFO - Started process 6373 to run task
[2023-02-09T15:20:36.690+0000] {standard_task_runner.py:82} INFO - Running: ['***', 'tasks', 'run', 'my_third_dagV1', 'fo', 'manual__2023-02-09T15:09:27.365823+00:00', '--job-id', '26', '--raw', '--subdir', 'DAGS_FOLDER/dag3.py', '--cfg-path', '/tmp/tmpl_6awu5q']
[2023-02-09T15:20:36.691+0000] {standard_task_runner.py:83} INFO - Job 26: Subtask fo
[2023-02-09T15:20:36.772+0000] {task_command.py:388} INFO - Running <TaskInstance: my_third_dagV1.fo manual__2023-02-09T15:09:27.365823+00:00 [running]> on host 47e55e08a495
[2023-02-09T15:20:36.840+0000] {taskinstance.py:1509} INFO - Exporting the following env vars:
AIRFLOW_CTX_DAG_OWNER=***
AIRFLOW_CTX_DAG_ID=my_third_dagV1
AIRFLOW_CTX_TASK_ID=fo
AIRFLOW_CTX_EXECUTION_DATE=2023-02-09T15:09:27.365823+00:00
AIRFLOW_CTX_TRY_NUMBER=5
AIRFLOW_CTX_DAG_RUN_ID=manual__2023-02-09T15:09:27.365823+00:00
[2023-02-09T15:20:38.394+0000] {taskinstance.py:1768} ERROR - Task failed with exception
Traceback (most recent call last):
  File "/home/airflow/.local/lib/python3.7/site-packages/airflow/operators/python.py", line 175, in execute
    return_value = self.execute_callable()
  File "/home/airflow/.local/lib/python3.7/site-packages/airflow/operators/python.py", line 192, in execute_callable
    return self.python_callable(*self.op_args, **self.op_kwargs)
  File "/opt/airflow/dags/dag3.py", line 57, in foo1
    dbConnection    = alchemyEngine.connect();
NameError: name 'alchemyEngine' is not defined
[2023-02-09T15:20:38.401+0000] {taskinstance.py:1323} INFO - Marking task as FAILED. dag_id=my_third_dagV1, task_id=fo, execution_date=20230209T150927, start_date=20230209T152036, end_date=20230209T152038
[2023-02-09T15:20:38.412+0000] {standard_task_runner.py:105} ERROR - Failed to execute job 26 for task fo (name 'alchemyEngine' is not defined; 6373)
[2023-02-09T15:20:38.448+0000] {local_task_job.py:208} INFO - Task exited with return code 1
[2023-02-09T15:20:38.471+0000] {taskinstance.py:2578} INFO - 0 downstream tasks scheduled from follow-on schedule check
