[2023-01-30T14:14:23.131+0000] {taskinstance.py:1083} INFO - Dependencies all met for <TaskInstance: my_third_dagV1.fo manual__2023-01-30T14:14:22.366603+00:00 [queued]>
[2023-01-30T14:14:23.141+0000] {taskinstance.py:1083} INFO - Dependencies all met for <TaskInstance: my_third_dagV1.fo manual__2023-01-30T14:14:22.366603+00:00 [queued]>
[2023-01-30T14:14:23.141+0000] {taskinstance.py:1279} INFO - 
--------------------------------------------------------------------------------
[2023-01-30T14:14:23.141+0000] {taskinstance.py:1280} INFO - Starting attempt 1 of 1
[2023-01-30T14:14:23.141+0000] {taskinstance.py:1281} INFO - 
--------------------------------------------------------------------------------
[2023-01-30T14:14:23.153+0000] {taskinstance.py:1300} INFO - Executing <Task(PythonOperator): fo> on 2023-01-30 14:14:22.366603+00:00
[2023-01-30T14:14:23.157+0000] {standard_task_runner.py:55} INFO - Started process 818 to run task
[2023-01-30T14:14:23.160+0000] {standard_task_runner.py:82} INFO - Running: ['***', 'tasks', 'run', 'my_third_dagV1', 'fo', 'manual__2023-01-30T14:14:22.366603+00:00', '--job-id', '5', '--raw', '--subdir', 'DAGS_FOLDER/dag3.py', '--cfg-path', '/tmp/tmp161nuy2l']
[2023-01-30T14:14:23.161+0000] {standard_task_runner.py:83} INFO - Job 5: Subtask fo
[2023-01-30T14:14:23.225+0000] {task_command.py:388} INFO - Running <TaskInstance: my_third_dagV1.fo manual__2023-01-30T14:14:22.366603+00:00 [running]> on host 7b03a031af5e
[2023-01-30T14:14:23.306+0000] {taskinstance.py:1509} INFO - Exporting the following env vars:
AIRFLOW_CTX_DAG_OWNER=***
AIRFLOW_CTX_DAG_ID=my_third_dagV1
AIRFLOW_CTX_TASK_ID=fo
AIRFLOW_CTX_EXECUTION_DATE=2023-01-30T14:14:22.366603+00:00
AIRFLOW_CTX_TRY_NUMBER=1
AIRFLOW_CTX_DAG_RUN_ID=manual__2023-01-30T14:14:22.366603+00:00
[2023-01-30T14:14:23.536+0000] {taskinstance.py:1768} ERROR - Task failed with exception
Traceback (most recent call last):
  File "/home/airflow/.local/lib/python3.7/site-packages/airflow/operators/python.py", line 175, in execute
    return_value = self.execute_callable()
  File "/home/airflow/.local/lib/python3.7/site-packages/airflow/operators/python.py", line 192, in execute_callable
    return self.python_callable(*self.op_args, **self.op_kwargs)
  File "/opt/airflow/dags/dag3.py", line 21, in foo1
    import matplotlib.pyplot as plt
ModuleNotFoundError: No module named 'matplotlib'
[2023-01-30T14:14:23.546+0000] {taskinstance.py:1323} INFO - Marking task as FAILED. dag_id=my_third_dagV1, task_id=fo, execution_date=20230130T141422, start_date=20230130T141423, end_date=20230130T141423
[2023-01-30T14:14:23.558+0000] {standard_task_runner.py:105} ERROR - Failed to execute job 5 for task fo (No module named 'matplotlib'; 818)
[2023-01-30T14:14:23.579+0000] {local_task_job.py:208} INFO - Task exited with return code 1
[2023-01-30T14:14:23.595+0000] {taskinstance.py:2578} INFO - 0 downstream tasks scheduled from follow-on schedule check
