[2023-04-15T19:45:45.679+0000] {taskinstance.py:1083} INFO - Dependencies all met for <TaskInstance: my_third_dagV1.fo manual__2023-04-15T19:45:44.771494+00:00 [queued]>
[2023-04-15T19:45:45.686+0000] {taskinstance.py:1083} INFO - Dependencies all met for <TaskInstance: my_third_dagV1.fo manual__2023-04-15T19:45:44.771494+00:00 [queued]>
[2023-04-15T19:45:45.686+0000] {taskinstance.py:1279} INFO - 
--------------------------------------------------------------------------------
[2023-04-15T19:45:45.686+0000] {taskinstance.py:1280} INFO - Starting attempt 1 of 1
[2023-04-15T19:45:45.686+0000] {taskinstance.py:1281} INFO - 
--------------------------------------------------------------------------------
[2023-04-15T19:45:45.766+0000] {taskinstance.py:1300} INFO - Executing <Task(PythonOperator): fo> on 2023-04-15 19:45:44.771494+00:00
[2023-04-15T19:45:45.771+0000] {standard_task_runner.py:55} INFO - Started process 484 to run task
[2023-04-15T19:45:45.773+0000] {standard_task_runner.py:82} INFO - Running: ['***', 'tasks', 'run', 'my_third_dagV1', 'fo', 'manual__2023-04-15T19:45:44.771494+00:00', '--job-id', '88', '--raw', '--subdir', 'DAGS_FOLDER/dag3.py', '--cfg-path', '/tmp/tmpkm6k5cd8']
[2023-04-15T19:45:45.774+0000] {standard_task_runner.py:83} INFO - Job 88: Subtask fo
[2023-04-15T19:45:45.877+0000] {task_command.py:388} INFO - Running <TaskInstance: my_third_dagV1.fo manual__2023-04-15T19:45:44.771494+00:00 [running]> on host 47e55e08a495
[2023-04-15T19:45:45.979+0000] {taskinstance.py:1509} INFO - Exporting the following env vars:
AIRFLOW_CTX_DAG_OWNER=***
AIRFLOW_CTX_DAG_ID=my_third_dagV1
AIRFLOW_CTX_TASK_ID=fo
AIRFLOW_CTX_EXECUTION_DATE=2023-04-15T19:45:44.771494+00:00
AIRFLOW_CTX_TRY_NUMBER=1
AIRFLOW_CTX_DAG_RUN_ID=manual__2023-04-15T19:45:44.771494+00:00
[2023-04-15T19:45:52.761+0000] {taskinstance.py:1768} ERROR - Task failed with exception
Traceback (most recent call last):
  File "/home/airflow/.local/lib/python3.7/site-packages/airflow/operators/python.py", line 175, in execute
    return_value = self.execute_callable()
  File "/home/airflow/.local/lib/python3.7/site-packages/airflow/operators/python.py", line 192, in execute_callable
    return self.python_callable(*self.op_args, **self.op_kwargs)
  File "/opt/airflow/dags/dag3.py", line 54, in foo1
    from pyspark.sql import Row
ModuleNotFoundError: No module named 'pyspark'
[2023-04-15T19:45:52.880+0000] {taskinstance.py:1323} INFO - Marking task as FAILED. dag_id=my_third_dagV1, task_id=fo, execution_date=20230415T194544, start_date=20230415T194545, end_date=20230415T194552
[2023-04-15T19:45:53.012+0000] {standard_task_runner.py:105} ERROR - Failed to execute job 88 for task fo (No module named 'pyspark'; 484)
[2023-04-15T19:45:53.059+0000] {local_task_job.py:208} INFO - Task exited with return code 1
[2023-04-15T19:45:53.070+0000] {taskinstance.py:2578} INFO - 0 downstream tasks scheduled from follow-on schedule check
