[2023-04-15T19:45:46.183+0000] {taskinstance.py:1083} INFO - Dependencies all met for <TaskInstance: my_third_dagV1.fo scheduled__2023-04-02T00:00:00+00:00 [queued]>
[2023-04-15T19:45:46.195+0000] {taskinstance.py:1083} INFO - Dependencies all met for <TaskInstance: my_third_dagV1.fo scheduled__2023-04-02T00:00:00+00:00 [queued]>
[2023-04-15T19:45:46.195+0000] {taskinstance.py:1279} INFO - 
--------------------------------------------------------------------------------
[2023-04-15T19:45:46.195+0000] {taskinstance.py:1280} INFO - Starting attempt 1 of 1
[2023-04-15T19:45:46.195+0000] {taskinstance.py:1281} INFO - 
--------------------------------------------------------------------------------
[2023-04-15T19:45:46.242+0000] {taskinstance.py:1300} INFO - Executing <Task(PythonOperator): fo> on 2023-04-02 00:00:00+00:00
[2023-04-15T19:45:46.246+0000] {standard_task_runner.py:55} INFO - Started process 487 to run task
[2023-04-15T19:45:46.248+0000] {standard_task_runner.py:82} INFO - Running: ['***', 'tasks', 'run', 'my_third_dagV1', 'fo', 'scheduled__2023-04-02T00:00:00+00:00', '--job-id', '89', '--raw', '--subdir', 'DAGS_FOLDER/dag3.py', '--cfg-path', '/tmp/tmp2jevc8x4']
[2023-04-15T19:45:46.249+0000] {standard_task_runner.py:83} INFO - Job 89: Subtask fo
[2023-04-15T19:45:46.300+0000] {task_command.py:388} INFO - Running <TaskInstance: my_third_dagV1.fo scheduled__2023-04-02T00:00:00+00:00 [running]> on host 47e55e08a495
[2023-04-15T19:45:46.366+0000] {taskinstance.py:1509} INFO - Exporting the following env vars:
AIRFLOW_CTX_DAG_OWNER=***
AIRFLOW_CTX_DAG_ID=my_third_dagV1
AIRFLOW_CTX_TASK_ID=fo
AIRFLOW_CTX_EXECUTION_DATE=2023-04-02T00:00:00+00:00
AIRFLOW_CTX_TRY_NUMBER=1
AIRFLOW_CTX_DAG_RUN_ID=scheduled__2023-04-02T00:00:00+00:00
[2023-04-15T19:45:52.761+0000] {taskinstance.py:1768} ERROR - Task failed with exception
Traceback (most recent call last):
  File "/home/airflow/.local/lib/python3.7/site-packages/airflow/operators/python.py", line 175, in execute
    return_value = self.execute_callable()
  File "/home/airflow/.local/lib/python3.7/site-packages/airflow/operators/python.py", line 192, in execute_callable
    return self.python_callable(*self.op_args, **self.op_kwargs)
  File "/opt/airflow/dags/dag3.py", line 54, in foo1
    from pyspark.sql import Row
ModuleNotFoundError: No module named 'pyspark'
[2023-04-15T19:45:52.880+0000] {taskinstance.py:1323} INFO - Marking task as FAILED. dag_id=my_third_dagV1, task_id=fo, execution_date=20230402T000000, start_date=20230415T194546, end_date=20230415T194552
[2023-04-15T19:45:53.012+0000] {standard_task_runner.py:105} ERROR - Failed to execute job 89 for task fo (No module named 'pyspark'; 487)
[2023-04-15T19:45:53.039+0000] {local_task_job.py:208} INFO - Task exited with return code 1
[2023-04-15T19:45:53.052+0000] {taskinstance.py:2578} INFO - 0 downstream tasks scheduled from follow-on schedule check
