[2023-04-27T12:01:18.229+0000] {taskinstance.py:1083} INFO - Dependencies all met for <TaskInstance: my_third_dagV1.fo scheduled__2023-04-16T00:00:00+00:00 [queued]>
[2023-04-27T12:01:18.413+0000] {taskinstance.py:1083} INFO - Dependencies all met for <TaskInstance: my_third_dagV1.fo scheduled__2023-04-16T00:00:00+00:00 [queued]>
[2023-04-27T12:01:18.414+0000] {taskinstance.py:1279} INFO - 
--------------------------------------------------------------------------------
[2023-04-27T12:01:18.414+0000] {taskinstance.py:1280} INFO - Starting attempt 1 of 1
[2023-04-27T12:01:18.414+0000] {taskinstance.py:1281} INFO - 
--------------------------------------------------------------------------------
[2023-04-27T12:01:18.437+0000] {taskinstance.py:1300} INFO - Executing <Task(PythonOperator): fo> on 2023-04-16 00:00:00+00:00
[2023-04-27T12:01:18.444+0000] {standard_task_runner.py:55} INFO - Started process 349 to run task
[2023-04-27T12:01:18.446+0000] {standard_task_runner.py:82} INFO - Running: ['***', 'tasks', 'run', 'my_third_dagV1', 'fo', 'scheduled__2023-04-16T00:00:00+00:00', '--job-id', '111', '--raw', '--subdir', 'DAGS_FOLDER/dag3.py', '--cfg-path', '/tmp/tmplzazaecz']
[2023-04-27T12:01:18.447+0000] {standard_task_runner.py:83} INFO - Job 111: Subtask fo
[2023-04-27T12:01:18.517+0000] {task_command.py:388} INFO - Running <TaskInstance: my_third_dagV1.fo scheduled__2023-04-16T00:00:00+00:00 [running]> on host 81b61dc43448
[2023-04-27T12:01:19.286+0000] {taskinstance.py:1509} INFO - Exporting the following env vars:
AIRFLOW_CTX_DAG_OWNER=***
AIRFLOW_CTX_DAG_ID=my_third_dagV1
AIRFLOW_CTX_TASK_ID=fo
AIRFLOW_CTX_EXECUTION_DATE=2023-04-16T00:00:00+00:00
AIRFLOW_CTX_TRY_NUMBER=1
AIRFLOW_CTX_DAG_RUN_ID=scheduled__2023-04-16T00:00:00+00:00
[2023-04-27T12:01:57.061+0000] {taskinstance.py:1768} ERROR - Task failed with exception
Traceback (most recent call last):
  File "/home/airflow/.local/lib/python3.7/site-packages/airflow/operators/python.py", line 175, in execute
    return_value = self.execute_callable()
  File "/home/airflow/.local/lib/python3.7/site-packages/airflow/operators/python.py", line 192, in execute_callable
    return self.python_callable(*self.op_args, **self.op_kwargs)
  File "/opt/airflow/dags/dag3.py", line 63, in foo1
    spark=SparkSession.builder.appName('Sparkv1').getOrCreate()
  File "/home/airflow/.local/lib/python3.7/site-packages/pyspark/sql/session.py", line 269, in getOrCreate
    sc = SparkContext.getOrCreate(sparkConf)
  File "/home/airflow/.local/lib/python3.7/site-packages/pyspark/context.py", line 483, in getOrCreate
    SparkContext(conf=conf or SparkConf())
  File "/home/airflow/.local/lib/python3.7/site-packages/pyspark/context.py", line 195, in __init__
    SparkContext._ensure_initialized(self, gateway=gateway, conf=conf)
  File "/home/airflow/.local/lib/python3.7/site-packages/pyspark/context.py", line 417, in _ensure_initialized
    SparkContext._gateway = gateway or launch_gateway(conf)
  File "/home/airflow/.local/lib/python3.7/site-packages/pyspark/java_gateway.py", line 106, in launch_gateway
    raise RuntimeError("Java gateway process exited before sending its port number")
RuntimeError: Java gateway process exited before sending its port number
[2023-04-27T12:01:57.133+0000] {taskinstance.py:1323} INFO - Marking task as FAILED. dag_id=my_third_dagV1, task_id=fo, execution_date=20230416T000000, start_date=20230427T120118, end_date=20230427T120157
[2023-04-27T12:01:57.235+0000] {standard_task_runner.py:105} ERROR - Failed to execute job 111 for task fo (Java gateway process exited before sending its port number; 349)
[2023-04-27T12:01:57.276+0000] {local_task_job.py:208} INFO - Task exited with return code 1
[2023-04-27T12:01:57.301+0000] {taskinstance.py:2578} INFO - 0 downstream tasks scheduled from follow-on schedule check
